Workbook

Sheet Cover
I3: blog.lucidtext.com
C7: EB-5 Backlog Analysis and Backlog Data
C9: Updated as of: | D9: 46238
C10: Document link: | D10: https://www.dropbox.com/scl/fi/xkbkaox1hgepg6nn6v3l9/EB5-Backlog-Analysis.xlsx?rlkey=iwnaj84r7apd0matmr0vagkq2&dl=0 | K10: .
D11: https://blog.lucidtext.com/eb-5-timing/
C12: Table of Contents
C13: Orientation | D13: Summarize what's known and unknown related to EB-5 visa availability and timing
C14: Summary 1 | D14: One way of looking at the supply/demand balance for EB-5 set-aside visas (starting from data through March 2026, and including a priority date estimator)
C15: Unreserved | D15: A calculator for estimating pre-RIA legacy backlog status and progress
C16: Infra | D16: FYI: A collection of research on Infrastructure demand
C17: Progress | D17: FYI: Collection of data related to progress in issuing Reserved visas and advancing pipeline applicants to the visa stage
C18: Pre-RIA Data | D18: FYI: Collection of pre-RIA data with source links
C19: Post-RIA Data | D19: FYI: Collection of post-RIA data with source links
C20: VB Log | D20: FYI: Log of past visa bulletins
C21: Notes | D21: Log of major updates and revisions to the model.
C23: Supporting Article Link:
C24: https://blog.lucidtext.com/2026/03/05/eb-5-set-aside-visa-backlog-and-outlook-update-as-of-march-2026-set-aside-backlog-size-unreserved-visa-availability-infrastructure-visa-bulletin-outlook/ | K24: .
C26: Contact:
C27: Email suzanne@lucidtext.com with any corrections or suggestions to improve this model.
C28: If you'd like Suzanne to talk through analysis and data relevant to your specific questions, you're welcome to schedule a consultation using the meeting link below.
D29: https://calendly.com/suzanne-lucid
C31: Note:
C32: This workbook analyzes a volatile reality. The model is populated with assumptions that may not be realized, and it pieces together incomplete data. Despite the author's best efforts, there may be errors in formulas or reasoning. (Email suzanne@lucidtext.com if you identify any!) The model is subject to regular revision and updates, as the situation evolves and more information becomes available. The model is offered as a tool to help support your own analysis. Do not rely on the model's default assumptions or conclusions a primary basis for decision-making. This workbook was created and is maintained by Suzanne Lazicki of blog.lucidtext.com.

Sheet Orientation
A1: The Big Picture
A14: What's Known as of January 2026
B15: Unreserved visa demand
C16: Pending I-485 through October 2025, National Visa Center data as of May 2024
B17: Rural and High Unemployment visa demand
C18: I-526/I-526E receipts and approvals to July 2025
B19: Infrastructure visa demand
C20: anecdotal reports about projects (USCIS has reported no receipt or approval data)
B21: Past visa issuance through mid 2025
B22: Average future visa availability
B23: I-526/I-526E approval letters since 2022 list Unreserved as well as Reserved categories, NVC has published a process for consular applicants to select from the category options, and USCIS has not yet published a process for AOS to make the selection
A25: Major Questions as of January 2026
B26: Questions about demand
C27: Investor trend (How many more investors since last data report, in which categories?)
C28: Investors-to-future visas (Family size? Denials and attrition over time?)
B29: Questions about visa supply & allocation
C30: # set-aside visas issued to-date and before retrogression
D31: recent petition approval and visa issuance volumes
D32: when will Rural, HUA, and Infra retrogress?
C33: # set-aside visas potentially unused by Rest of World, available above country cap to China and India
D34: ROW investor volume
D35: ROW applicant option and willingness to choose Unreserved
D36: how unused visas set-asides shared between China/India above country caps
C37: # Unreserved visas available to set-aside investors
D38: when will pre-2022 Unreserved backlogs be clear
D39: how will Unreserved visas be divided between Rural, HUA, infra
D40: how much friction in the option for a set-aside investor to request an Unreserved visa
D41: whether a significant difference between consular and AOS ability to access Unreserved
D42: whether a non-TEA investor would have priority for an Unreserved visa over a set-aside investor with an earlier priority date

Sheet Summary1
B2: SUPPLY DETAIL
B3: Typical Annual EB-5 Visa Limits
C4: EB-5 Total | D4: Rural Set Aside | E4: High Unemployment Set Aside | F4: Infrastructure Set Aside | G4: Unreserved
C5: 1 | D5: 0.2 | E5: 0.1 | F5: 0.02 | G5: =C5-SUM(D5:F5) -> 0.68
B6: Base EB Limit | C6: 140000
B7: Total Base Annual EB-5 Visas (rounded) | C7: =ROUNDUP(C6*I7,-2) -> 10000 | D7: =$C$7*D5 -> 2000 | E7: =$C$7*E5 -> 1000 | F7: =$C$7*F5 -> 200 | G7: =C7-SUM(D7:F7) -> 6800 | I7: 0.071
B8: China Minimum (country cap 7%) | C8: =C$7*$H8 -> 700 | D8: =D$7*$H8 -> 140 | E8: =E$7*$H8 -> 70 | F8: =F$7*$H8 -> 14 | G8: =G$7*$H8 -> 476 | H8: 0.07
B9: India Minimum (country cap 7%) | C9: =C$7*$H9 -> 700 | D9: =D$7*$H9 -> 140 | E9: =E$7*$H9 -> 70 | F9: =F$7*$H9 -> 14 | G9: =G$7*$H9 -> 476 | H9: 0.07
B10: Rest of World (ROW) Maximum (86%) | C10: =C$7*$H10 -> 8600 | D10: =D$7*$H10 -> 1720 | E10: =E$7*$H10 -> 860 | F10: =F$7*$H10 -> 172 | G10: =G$7*$H10 -> 5848 | H10: =1-H8-H9 -> 0.86
B12: Scenario with large FB rollover | C12: 15000 | D12: =$C$12*D5 -> 3000 | E12: =$C$12*E5 -> 1500 | F12: =$C$12*F5 -> 300 | G12: =$C$12*G5 -> 10200
B14: Supply notes:
B15: The typical annual EB-5 visa allocation follows from the base annual 140,000 EB visas. The actual EB limit can be higher due to rollover of FB visas unused in the previous year.
B16: China and India may receive visas above the 7% country cap if ROW does not claim its maximum visas
B17: Actual annual visas can be slightly below or well above 10,000 depending on rollover from family-based in previous year, or carryover from unused Reserved EB-5
B18: Actual visas issued can be lower than the annual limit, due to lack of applicants or to government processing constraints
B19: When new set-aside visas are unused one year, they carry over in the same set aside category the next year
B20: When carried-over set-aside visas are unused for a second year, they carry to Unreserved for the 3rd year.
B21: In theory, set aside investors can qualify for a set-aside visa or an Unreserved visa.
B23: EB-5 Visa Issuance 2022-2025 | J23: Total 2022-2025
C24: EB-5 Total | D24: Rural Set Aside | E24: High Unemployment Set Aside | F24: Infrastructure Set Aside | G24: Unreserved | K24: Set-Aside Total | L24: Rural Set Aside | M24: High Unemployment Set Aside | N24: Infrastructure Set Aside
B25: FY2022 (actual) | C25: =SUM(D25:G25) -> 10885 | D25: =Progress!C120 -> 0 | E25: =Progress!C128 -> 0 | F25: =Progress!C137 -> 0 | G25: =Progress!C149 -> 10885 | J25: China | K25: =SUM(L25:N25) -> 1395 | L25: =Progress!K117 -> 1181 | M25: =Progress!K125 -> 214 | N25: =Progress!K134 -> 0
B26: FY2023 (actual) | C26: =SUM(D26:G26) -> 9817 | D26: =Progress!D120 -> 0 | E26: =Progress!D128 -> 0 | F26: =Progress!D137 -> 0 | G26: =Progress!C150 -> 9817 | J26: India | K26: =SUM(L26:N26) -> 1185 | L26: =Progress!K118 -> 833 | M26: =Progress!K126 -> 352 | N26: =Progress!K135 -> 0
B27: FY2024 (actual) | C27: =SUM(D27:G27) -> 14924 | D27: =Progress!E120 -> 332 | E27: =Progress!E128 -> 91 | F27: =Progress!E137 -> 0 | G27: =Progress!C151 -> 14501 | J27: ROW | K27: =SUM(L27:N27) -> 633 | L27: =Progress!K119 -> 248 | M27: =Progress!K127 -> 385 | N27: =Progress!K136 -> 0
B28: FY2025 (estimate) | C28: =SUM(D28:G28) -> 14260 | D28: =Progress!J120 -> 1930 | E28: =Progress!J128 -> 860 | F28: =Progress!J137 -> 0 | G28: =Progress!C152 -> 11470 | K28: =SUM(K25:K27) -> 3213 | L28: =SUM(L25:L27) -> 2262 | M28: =SUM(M25:M27) -> 951 | N28: =SUM(N25:N27) -> 0
B29: Total 2022-2025 | D29: =SUM(D25:D28) -> 2262 | E29: =SUM(E25:E28) -> 951 | F29: =SUM(F25:F28) -> 0
B30: In 2022-2025, set-aside visa issuance was limited by government processing constraints, while the available limit was expanded by rollover and carryover visas due to lack of usage in previous years.
B32: DEMAND | L32: Forecast another date | M32: 46266
B33: Actual INVESTORS with priority dates between April 1, 2022 and March 31, 2026 | L33: Months since 3/31/2026 | M33: =(M32-N33)/30.5 -> 5.0491803 | N33: 46112
B34: Total I-526/I-526E filings April 1, 2022 to March 31, 2026 | L34: Guess monthly demand compared previous 9 months average | M34: 1
C35: Total | D35: Rural | E35: High Unemployment | F35: Infrastructure | G35: Other** | H35: Total | I35: Rural | L35: Rural | M35: High Unemployment
B36: CHINA | C36: =SUM(D36:G36) -> 8580 | D36: ='Post-RIA'!P4 -> 4881 | E36: ='Post-RIA'!Q4 -> 3438 | F36: ='Post-RIA'!R4 -> 0 | G36: ='Post-RIA'!S4 -> 261 | H36: =C36/(C36+C37) -> 0.64931134 | I36: =D36/(D36+D37) -> 0.65728521 | K36: CHINA | L36: =D36+D42/6*$M$33*$M$34 -> 5600.5082 | M36: =E36+E42/6*$M$33*$M$34 -> 3778.8197
B37: INDIA | C37: =SUM(D37:G37) -> 4634 | D37: ='Post-RIA'!P5 -> 2545 | E37: ='Post-RIA'!Q5 -> 1806 | F37: ='Post-RIA'!R5 -> 0 | G37: ='Post-RIA'!S5 -> 283 | H37: =C37/(C37+C36) -> 0.35068866 | I37: =D37/(D37+D36) -> 0.34271479 | K37: INDIA | L37: =D37+D43/6*$M$33*$M$34 -> 3198.0273 | M37: =E37+E43/6*$M$33*$M$34 -> 2164.4918
B38: Rest of World | C38: =SUM(D38:G38) -> 4901 | D38: ='Post-RIA'!P6 -> 1380 | E38: ='Post-RIA'!Q6 -> 2971 | F38: ='Post-RIA'!R6 -> 0 | G38: ='Post-RIA'!S6 -> 550 | K38: Rest of World | L38: =D38+D44/6*$M$33*$M$34 -> 1604.6885 | M38: =E38+E44/6*$M$33*$M$34 -> 3338.7486
B39: Total | C39: =SUM(C36:C38) -> 18115 | D39: =SUM(D36:D38) -> 8806 | E39: =SUM(E36:E38) -> 8215 | F39: =SUM(F36:F38) -> 0 | G39: =SUM(G36:G38) -> 1094 | K39: Total | L39: =SUM(L36:L38) -> 10403.224 | M39: =SUM(M36:M38) -> 9282.0601
D40: =D39/C39 -> 0.48611648 | E40: =E39/C39 -> 0.45349158
B41: I-526/I-526E filings October 2025-March 2026 (6 months) | C41: Total | D41: Rural | E41: High Unemployment | F41: Infrastructure | G41: Other** | K41: CHINA | L41: =L36/M36 -> 1.4820787
B42: CHINA | C42: =SUM(D42:G42) -> 1361 | D42: ='Post-RIA'!P10 -> 855 | E42: ='Post-RIA'!Q10 -> 405 | F42: ='Post-RIA'!R10 -> 0 | G42: ='Post-RIA'!S10 -> 101 | H42: =C42/(C42+C43) -> 0.50314233 | I42: =D42/(D42+D43) -> 0.52421827 | K42: INDIA | L42: =L37/M37 -> 1.4774957
B43: INDIA | C43: =SUM(D43:G43) -> 1344 | D43: ='Post-RIA'!P11 -> 776 | E43: ='Post-RIA'!Q11 -> 426 | F43: ='Post-RIA'!R11 -> 0 | G43: ='Post-RIA'!S11 -> 142 | H43: =C43/(C43+C42) -> 0.49685767 | I43: =D43/(D43+D42) -> 0.47578173 | K43: Rest of World | L43: =L38/M38 -> 0.48062574
B44: Rest of World | C44: =SUM(D44:G44) -> 854 | D44: ='Post-RIA'!P12 -> 267 | E44: ='Post-RIA'!Q12 -> 437 | F44: ='Post-RIA'!R12 -> 0 | G44: ='Post-RIA'!S12 -> 150
B45: Total | C45: =SUM(C42:C44) -> 3559 | D45: =SUM(D42:D44) -> 1898 | E45: =SUM(E42:E44) -> 1268 | F45: =SUM(F42:F44) -> 0 | G45: =SUM(G42:G44) -> 393 | L45: 140 | M45: 70
...

Sheet Summary2
B1: Estimated EB-5 Set-Aside Visa Backlog Size and Progress as of March 2026
D3: All Countries | G3: China | J3: India | M3: Rest of World
D4: Rural | E4: High Unemployment | F4: Infra-structure | G4: Rural | H4: High Unemployment | I4: Infra-structure | J4: Rural | K4: High Unemployment | L4: Infra-structure | M4: Rural | N4: High Unemployment | O4: Infra-structure
C5: USCIS data for I-526/I-526E (AIIA FOIA)
C6: (data from USCIS via AIIA FOIA)
C7: Total April 2022 to July 2025
B8: A | C8: I-526/I-526E Receipts Apr-2022 to Jul-2025 | D8: 6406 | E8: 6582 | F8: 0 | G8: 3845 | H8: 2926 | I8: 0 | J8: 1636 | K8: 1264 | L8: 0 | M8: 925 | N8: 2392 | O8: 0
B9: B | C9: I-526/I-526E Approvals Apr-2022 to Jul-2025 | D9: 2819 | E9: 545 | F9: 0 | G9: 1663 | H9: 98 | I9: 0 | J9: 725 | K9: 217 | L9: 0 | M9: 431 | N9: 230 | O9: 0
B10: C | C10: I-526/I-526E Denials Apr-2022 to Jul-2025 | D10: 62 | E10: 13 | F10: 0 | G10: 46 | H10: 6 | I10: 0 | J10: 5 | K10: 1 | L10: 0 | M10: 11 | N10: 6 | O10: 0
C11: Recent trend (previous reported 7 months)
B12: A.2⊂A | C12: I-526/I-526E Receipts Jan-2025 to Jul-2025 | D12: 2398 | E12: 1628 | F12: 0 | G12: 1269 | H12: 664 | I12: 0 | J12: 841 | K12: 415 | L12: 0 | M12: 288 | N12: 549 | O12: 0
B13: B.2⊂B | C13: I-526/I-526E Approvals Jan-2025 to Jul-2025 | D13: 1693 | E13: 194 | F13: 0 | G13: 934 | H13: 19 | I13: 0 | J13: 477 | K13: 105 | L13: 0 | M13: 282 | N13: 70 | O13: 0
C14: Estimated recent changes
C15: (Rural & HUA guess based on previous 7 months; Infra rough guess from project info online)
B16: D≈A.2 | C16: Estimated receipts Aug-25 to Feb-26 | D16: =ROUND(D12,-1) -> 2400 | E16: =ROUND(E12,-1) -> 1630 | F16: =Infra!M34 -> 529 | G16: =ROUND(G12,-1) -> 1270 | H16: =ROUND(H12,-1) -> 660 | I16: =Infra!M31 -> 211.6 | J16: =ROUND(J12,-1) -> 840 | K16: =ROUND(K12,-1) -> 420 | L16: =Infra!M32 -> 105.8 | M16: =ROUND(M12,-1) -> 290 | N16: =ROUND(N12,-1) -> 550 | O16: =Infra!M33 -> 211.6
B17: E≈B.2 | C17: Estimated approvals Aug-25 to Feb-26 | D17: =ROUND(D13,-1) -> 1690 | E17: =ROUND(E13,-1) -> 190 | F17: =Infra!N34 -> 130 | G17: =ROUND(G13,-1) -> 930 | H17: =ROUND(H13,-1) -> 20 | I17: =Infra!N31 -> 30 | J17: =ROUND(J13,-1) -> 480 | K17: =ROUND(K13,-1) -> 110 | L17: =Infra!N32 -> 20 | M17: =ROUND(M13,-1) -> 280 | N17: =ROUND(N13,-1) -> 70 | O17: =Infra!N33 -> 80
C18: Estimated total I-526/I-526E (rounded)
B19: F=A+D | C19: Estimated total receipts by March 2026 | D19: =ROUND(D8,-2)+D16 -> 8800 | E19: =ROUND(E8,-2)+E16 -> 8230 | F19: =ROUND(F8,-2)+F16 -> 529 | G19: =ROUND(G8,-2)+G16 -> 5070 | H19: =ROUND(H8,-2)+H16 -> 3560 | I19: =ROUND(I8,-2)+I16 -> 211.6 | J19: =ROUND(J8,-2)+J16 -> 2440 | K19: =ROUND(K8,-2)+K16 -> 1720 | ... O19: =ROUND(O8,-2)+O16 -> 211.6
B20: G=B+E | C20: Estimated total approvals by March 2026 | D20: =ROUND(D9,-2)+D17 -> 4490 | E20: =ROUND(E9,-2)+E17 -> 690 | F20: =ROUND(F9,-2)+F17 -> 130 | G20: =ROUND(G9,-2)+G17 -> 2630 | H20: =ROUND(H9,-2)+H17 -> 120 | I20: =ROUND(I9,-2)+I17 -> 30 | J20: =ROUND(J9,-2)+J17 -> 1180 | K20: =ROUND(K9,-2)+K17 -> 310 | ... O20: =ROUND(O9,-2)+O17 -> 80
C21: Estimated visa applicants up to March 2026
B22: H=(F-C)*2 | C22: Pipeline visa applicants | D22: =D19*2 -> 17600 | E22: =E19*2 -> 16460 | F22: =F19*2 -> 1058 | G22: =G19*2 -> 10140 | H22: =H19*2 -> 7120 | I22: =I19*2 -> 423.2 | J22: =J19*2 -> 4880 | K22: =K19*2 -> 3440 | ... O22: =O19*2 -> 423.2
B23: I=G*2 | C23: Qualified visa applicants | D23: =D20*2 -> 8980 | E23: =E20*2 -> 1380 | F23: =F20*2 -> 260 | G23: =G20*2 -> 5260 | H23: =H20*2 -> 240 | I23: =I20*2 -> 60 | J23: =J20*2 -> 2360 | K23: =K20*2 -> 620 | ... O23: =O20*2 -> 160
C24: Estimated visa issuance
C25: (assuming even trend since last 2025 data report)
B26: J | C26: Estimated visas issued 2022 to Oct 2025 | D26: =D56 -> 2300 | E26: =E56 -> 1000 | F26: =F56 -> 0 | I26: =I56 -> 0 | L26: =L56 -> 0 | O26: =O56 -> 0
B27: K | C27: Estimated visas issued 2022 to Feb 2026 | D27: =D57 -> 3100 | E27: =E57 -> 1400 | F27: =F57 -> 0 | I27: =I57 -> 0 | L27: =L57 -> 0 | O27: =O57 -> 0
C28: Estimated status as of March 2026
B29: L=H-K | C29: Est. pipeline applicants without visas as of Mar 26 | D29: =D22-D26 -> 15300 | E29: =E22-E26 -> 15460 | F29: =F22-F26 -> 1058 | G29: =G22-G26 -> 10140 | H29: =H22-H26 -> 7120 | I29: =I22-I26 -> 423.2 | J29: =J22-J26 -> 4880 | K29: =K22-K26 -> 3440 | ... O29: =O22-O26 -> 423.2
B30: M=I-J | C30: Est. qualified applicants without visas as of Oct 25 | D30: =D23-D26 -> 6680 | E30: =E23-E26 -> 380 | F30: =F23-F26 -> 260 | G30: =G23-G26 -> 5260 | H30: =H23-H26 -> 240 | I30: =I23-I26 -> 60 | J30: =J23-J26 -> 2360 | K30: =K23-K26 -> 620 | ... O30: =O23-O26 -> 160
C31: Visa Supply
B32: N | C32: Average annual set-aside visas (7% min or 86% max) | D32: 2000 | E32: 1000 | F32: 200 | G32: =D32*0.07 -> 140 | H32: =E32*0.07 -> 70 | I32: =$F$32*0.07 -> 14 | J32: =D32*0.07 -> 140 | K32: =E32*0.07 -> 70 | L32: =$F$32*0.07 -> 14 | M32: =D32-G32-J32 -> 1720 | N32: =E32-H32-K32 -> 860 | O32: =F32-I32-L32 -> 172
B33: O | C33: Estimated FY2026 visas | D33: 4000 | E33: 2000 | F33: 400
C34: Compare Demand with Supply
B35: P=L/N | C35: Compare pipeline applicants without visas with average annual visas | D35: =D29/D32 -> 7.65 | E35: =E29/E32 -> 15.46 | F35: =F29/F32 -> 5.29 | G35: =G29/G32 -> 72.428571 | H35: =H29/H32 -> 101.71429 | I35: =I29/I32 -> 30.228571 | J35: =J29/J32 -> 34.857143 | K35: =K29/K32 -> 49.142857 | ... O35: =O29/O32 -> 2.4604651
B36: Q=M/O | C36: Compare qualified applicants with FY2026 visas | D36: =D30/D33 -> 1.67 | E36: =E30/E33 -> 0.19 | F36: =F30/F33 -> 0.65
D38: All Countries | G38: China | J38: India | M38: Rest of World
C39: Compare Pre-RIA Unreserved Backlog
C40: Est. qualified applicants without visas as of Mar 26 | D40: =G40+J40+M40 -> 21800 | G40: =Unreserved!L15 -> 20200 | J40: =Unreserved!M15 -> 1100 | M40: =Unreserved!N15 -> 500
C42: Estimated total applicants without visas yet as of March 2026, Pre-RIA and Post-RIA | D42: =D40+(D29+E29+F29) -> 53618 | G42: =G40+(G29+H29+I29) -> 37883.2 | J42: =J40+(J29+K29+L29) -> 9631.6 | M42: =M40+(M29+N29+O29) -> 9203.2
B44: Sources:
...

Sheet Unreserved
B1: Pre-RIA Unreserved Backlog
B2: Available Data for Pre-RIA Unreserved Backlog (sources copied below)
C3: China Unreserved | F3: India Unreserved | I3: ROW Unreserved
B4: Data as of Date | C4: NVC waitlist registered applicants | D4: I-485 pending | E4: I-526 pending | F4: NVC waitlist registered applicants | G4: I-485 pending | H4: I-526 pending | I4: NVC waitlist registered applicants | J4: I-485 pending | K4: I-526 pending
C5: applicants | D5: applicants | E5: investors only | F5: applicants | G5: applicants | H5: investors only | I5: applicants | J5: applicants | K5: investors only
B6: as of 5/2024 | C6: 31255 | D6: 2571 | E6: 2974 | F6: 2541 | G6: 953 | H6: 473 | I6: 5774 | J6: 1367 | K6: 1049
B7: as of 10/2025 | C7: ? | D7: 4483 | E7: ? | F7: ? | G7: 721 | H7: ? | I7: ? | J7: 200 | K7: ?
B9: Estimated total pre-RIA Unreserved Backlog, and Backlog Progress | P9: Unreserved China VISA DEMAND ESTIMATE as of June 2024 | U9: Unreserved India VISA DEMAND ESTIMATE as of June 2024
C10: China Pre-RIA Unreserved | D10: India Pre-RIA Unreserved | E10: ROW Pre-RIA Unreserved | F10: Post-RIA Unreserved | G10: Total | H10: Refrence total on Supply tab Scenario 1 assuming large FB rollovers from visa blocks | J10: Refrence total on Supply tab Scenario 2 (minimal extra EB visas)
B11: Estimated total backlog as of May 2024 (estimated from data cited above, including assumptions about denials, attrition, and double counting) | C11: =(C6+D6*0.5+E6*0.5*2.5)*0.85 -> 30819.3 | D11: =(F6+G6*0.5+H6*0.7*2)*0.85 -> 3127.745 | E11: =(I6+J6*0.8+K6*0.7*2.5)*0.85 -> 7397.8475 | G11: =SUM(C11:E11) -> 41344.893 | P11: Priority Date | Q11: I-526 Filed (actual until 10/2020, estimate for 2021-2022) | R11: I-526 Pending as of 7/2024 (actual) | S11: Applicants registered at NVC as of 5/2024 (quarterly estimate from actual annual) | T11: I-485 Pending as of 6/2024 (actual) | U11: Priority Date | V11: I-526 Filed (actual) | W11: I-526 Pending as of 7/2024 (actual) | X11: Applicants registered at NVC as of 5/2024 (quarterly estimate from actual annual) | Y11: I-485 Pending as of 6/2024 (actual)
C12: China Unreserved | D12: India Unreserved | E12: ROW Unreserved | P12: Pre-2015 | R12: 6 | S12: 588 | T12: 0 | U12: Pre-FY2017 | W12: 0 | X12: 51
B13: Estimated visas issued in last 4 months of FY2024 | C13: =-Progress!D151*4/12 -> -3104 | D13: =-Progress!E151*4/12 -> -441 | E13: =-Progress!F151*4/12 -> -1288.6667 | G13: =SUM(C13:E13) -> -4833.6667 | H13: ='Visa Supply'!E67 -> 14207.109 | P13: 2015 Q1. Oct - Dec 2014 | Q13: 2783.0277 | R13: 1 | T13: 0 | U13: 2017 Q2. Jan - Mar 2017 | V13: 42 | W13: 0 | X13: 6.784217
B14: Estimated visas issued in FY2025 | C14: =-ROUNDUP(Progress!L106,-2) -> -4500 | D14: =-ROUNDUP(Progress!L107,-2) -> -1100 | E14: =-ROUNDUP(Progress!L108,-2) -> -5200 | G14: =SUM(C14:E14) -> -10800 | H14: ='Visa Supply'!F64 -> 11298.694 | P14: 2015 Q2. Jan - Mar 2015 | Q14: 2184.9748 | R14: 1 | S14: 1286.518 | T14: 0 | U14: 2017 Q3. April - June 2017 | V14: 261 | W14: 1 | X14: 42.159063
B15: Estimated pre-RIA applicants recorded as of 5/2024 who don't have visas yet at FY2026 start | C15: =ROUNDDOWN(C11+SUM(C13:C14),-2) -> 23200 | D15: =ROUNDDOWN(D11+SUM(D13:D14),-2) -> 1500 | E15: =ROUNDDOWN(E11+SUM(E13:E14),-2) -> 900 | G15: =SUM(C15:E15) -> 25600 | K15: Est as of 3/2026 | L15: =ROUND(C15+C16*5/12,-2) -> 20200 | M15: =ROUND(D15+D16*5/12,-2) -> 1100 | N15: =ROUND(E15+E16*5/12,-2) -> 500 | P15: 2015 Q3 Apr - Jun 2015 | Q15: 2340.1658 | R15: 3 | S15: 1377.8948 | T15: 14 | U15: 2017 Q4 Jul - Sep 2017 | V15: 127 | W15: 0 | X15: 20.51418
B16: Estimated visas issued FY2026 (optimistic assuming carryover and rollover from unused FB) | C16: -7100 | D16: -1000 | E16: -900 | G16: =SUM(C16:F16) -> -9000 | H16: ='Visa Supply'!G64 -> 9655.9715 | I16: =H16*0.07 -> 675.91801 | J16: ='Visa Supply'!R17 -> 9671.6142 | P16: 2015 Q4 Jul - Sep 2015 | Q16: 6221.8317 | R16: 28 | S16: 3663.4283 | T16: 89 | U16: 2018 Q1 Oct - Dec 2017 | V16: 381 | W16: 1 | X16: 61.54254
B17: Estimated visas issued FY2027 (optimistic assuming carryover and rollover from unused FB) | C17: -8200 | D17: -500 | F17: -1000 | G17: =SUM(C17:F17) -> -9700 | H17: ='Visa Supply'!H64 -> 9964.8406 | I17: =H17*0.07 -> 697.53884 | J17: ='Visa Supply'!S17 -> 7242 | P17: 2016 Q1 Oct - Dec 2015 | Q17: 3808 | R17: 33 | S17: 2242.1589 | T17: 118 | U17: 2018 Q2. Jan - Mar 2018 | V17: 283 | W17: 0 | X17: 179.41674
B18: FY2028 estimate (optimistic assuming rollover from unused FB) | C18: -5000 | F18: -4500 | G18: =SUM(C18:F18) -> -9500 | H18: ='Visa Supply'!I17 -> 9656 | I18: =H18*0.07 -> 675.92 | J18: ='Visa Supply'!T17 -> 6759.2 | P18: 2016 Q2 Jan - Mar 2016 | Q18: 391 | R18: 4 | S18: 545.90335 | T18: 98 | U18: 2018 Q3. April - June 2018 | V18: 127 | W18: 0 | X18: 80.515638
B19: FY2029 estimate | C19: -2900 | F19: -4500 | G19: =SUM(C19:F19) -> -7400 | H19: ='Visa Supply'!J17 -> 6759.2 | I19: =H19*0.07 -> 473.144 | J19: ='Visa Supply'!T17 -> 6759.2 | P19: 2016 Q3 April - June 2016 | Q19: 1415 | R19: 20 | S19: 1975.5837 | T19: 332 | U19: 2018 Q4 Jul - Sep 2018 | V19: 330 | W19: 3 | X19: 209.21386
B20: FY2030 estimate | G20: =SUM(C20:F20) -> 0 | P20: 2016 Q4 Jul - Sep 2016 | Q20: 5334 | R20: 79 | S20: 7447.1828 | T20: 1165 | U20: 2019 Q1 Oct - Dec 2018 | V20: 443 | W20: 1 | X20: 280.85376 | Y20: 45
B21: FY2031 estimate | P21: 2017 Q1 Oct - Dec 2016 | Q21: 3310 | R21: 87 | S21: 4621.3301 | T21: 782 | U21: 2019 Q2. Jan - Mar 2019 | V21: 155 | W21: 7 | X21: 93.769282 | Y21: 23
P22: 2017 Q2. Jan - Mar 2017 | Q22: 1172 | R22: 94 | S22: 1198.9144 | T22: 0 | U22: 2019 Q3. April - June 2019 | V22: 180 | W22: 3 | X22: 108.89336 | Y22: 44
B23: Balance of pre-RIA applicants | C23: =SUM(C15:C22) -> 0 | D23: =SUM(D15:D22) -> 0 | E23: =SUM(E15:E22) -> 0 | P23: 2017 Q3. April - June 2017 | Q23: 3280 | R23: 430 | S23: 3355.3236 | T23: 0 | U23: 2019 Q4 Jul - Sep 2019 | V23: 249 | W23: 9 | X23: 150.63581 | Y23: 99
B24: Estimated years from FY2026 to clear the Pre-RIA backlog | C24: =COUNTA(C16:C20) -> 4 | D24: =COUNTA(D16:D20) -> 2 | E24: =COUNTA(E16:E20) -> 1 | P24: 2017 Q4 Jul - Sep 2017 | Q24: 1009 | R24: 243 | S24: 1032.1712 | T24: 0 | U24: 2020 Q1 Oct - Dec 2019 | V24: 907 | W24: 153 | X24: 548.70154 | Y24: 404
P25: 2018 Q1 Oct - Dec 2017 | Q25: 1245 | R25: 326 | S25: 1273.5908 | T25: 0 | U25: 2020 Q2 Jan - Mar 2020 | V25: 6 | W25: 3 | X25: 0 | Y25: 0
C26: =SUM(C13:C14) -> -7604 | D26: =SUM(D13:D14) -> -1541 | E26: =SUM(E13:E14) -> -6488.6667 | G26: =SUM(G13:G14) -> -15633.667 | P26: 2018 Q2. Jan - Mar 2018 | Q26: 696 | R26: 358 | S26: 302 | T26: 0 | U26: 2020 Q3 Apr - Jun 2020 | V26: 11 | W26: 0 | X26: 2 | Y26: 0
B27: Data Sources | C27: https://www.uscis.gov/sites/default/files/document/data/eb_inventory_october_2025.xlsx | P27: 2018 Q3. April - June 2018 | Q27: 207 | R27: 154 | S27: 89.818966 | T27: 0 | U27: 2020 Q4 Jul - Sep 2020 | V27: 11 | W27: 2 | X27: 2 | Y27: 0
C28: https://www.uscis.gov/sites/default/files/document/reports/eb_inventory_may_2024_081324.xlsx | P28: 2018 Q4 Jul - Sep 2018 | Q28: 294 | R28: 277 | S28: 127.56897 | T28: 0 | U28: 2021 Q1 Oct - Dec 2020 | V28: 10 | W28: 2 | X28: 0 | Y28: 0
C29: https://iiusa.org/wp-content/uploads/2024/06/Insights-from-DOS-Recap-of-2024-IIUSA-EB-5-Forum-1.pdf | P29: 2019 Q1 Oct - Dec 2018 | Q29: 195 | R29: 144 | S29: 84.612069 | T29: 0 | U29: 2021 Q2 Jan - Mar 2021 | V29: 22 | W29: 6 | X29: 0 | Y29: 0
C30: https://goaiia.org/aiia-foia-series-pre-ria-i-526-data-as-of-july-2024/ | P30: 2019 Q2. Jan - Mar 2019 | Q30: 118 | R30: 99 | S30: 0 | T30: 0 | U30: 2021 Q3 Apr - Jun 2021 | V30: 180 | W30: 90 | X30: 44 | Y30: 94
C31: Report of the Visa Office 2024, and monthly visa issuance data through May 2025 | P31: 2019 Q3. April - June 2019 | Q31: 91 | R31: 80 | S31: 0 | T31: 0 | U31: 2021 Q4 Jul - Sep 2021 | V31: 37 | W31: 19 | X31: 0 | Y31: 22
C32: https://travel.state.gov/content/travel/en/legal/visa-law0/visa-statistics/ | P32: 2019 Q4 Jul - Sep 2019 | Q32: 118 | R32: 97 | S32: 0 | T32: 0 | U32: 2022 Q1 Oct - Dec 2021 | V32: 70 | W32: 25 | X32: 0 | Y32: 69
P33: 2020 Q1 Oct - Dec 2019 | Q33: 416 | R33: 369 | S33: 31 | T33: 0 | U33: 2022 Q2 Jan - Mar 2022 | V33: 195 | W33: 148 | Y33: 160
P34: 2020 Q2 Jan - Mar 2020 | Q34: 3 | R34: 2 | S34: 0 | T34: 0 | V34: =SUM(V12:V33) -> 4027 | W34: =SUM(W12:W33) -> 473 | X34: =SUM(X12:X33) -> 1882 | Y34: =SUM(Y12:Y33) -> 960
P35: 2020 Q3 Apr - Jun 2020 | Q35: 2 | R35: 2 | S35: 0 | T35: 0
P36: 2020 Q4 Jul - Sep 2020 | Q36: 7 | R36: 6 | S36: 0 | T36: 0
P37: 2021 Q1 Oct - Dec 2020 | Q37: =R37 -> 7 | R37: 7 | S37: 0 | T37: 0
P38: 2021 Q2 Jan - Mar 2021 | Q38: =R38 -> 6 | R38: 6 | S38: 0 | T38: 0
P39: 2021 Q3 Apr - Jun 2021 | Q39: =R39 -> 9 | R39: 9 | S39: 0 | T39: 0
P40: 2021 Q4 Jul - Sep 2021 | Q40: =R40 -> 0 | R40: 0 | S40: 0 | T40: 0
P41: 2022 Q1 Oct - Dec 2021 | Q41: =R41 -> 1 | R41: 1 | S41: 0 | T41: 0
...

Sheet Infra
B1: Infrastructure
D2: China | E2: India | F2: ROW | G2: Total
B3: Base annual infrastructure visa supply | D3: (min) | E3: (min) | F3: (max) | G3: 10000
C4: Normal Year | D4: =G4*0.07 -> 14 | E4: =G4*0.07 -> 14 | F4: =G4-E4-D4 -> 172 | G4: =G3*H4 -> 200 | H4: 0.02
C5: Carryover Year | D5: =G5*0.07 -> 28 | E5: =G5*0.07 -> 28 | F5: =G5-E5-D5 -> 344 | G5: =G4*2 -> 400
B6: Infrastructure demand reported by USCIS
C7: https://www.uscis.gov/tools/reports-and-studies/immigration-and-citizenship-data
D8: China | E8: India | F8: ROW | G8: Total
C9: Infrastructure I-526E filed through 12/31/2025 | D9: 0 reported | E9: 0 reported | F9: 0 reported
C10: Infrastructure I-485 pending as of 5/3/2025 | D10: =J47*10 -> 40 | E10: =J51*10 -> 60 | F10: =J61*10 -> 120 | G10: =SUM(D10:F10) -> 220
C11: Infrastructure I-485 pending as of 4/3/2026 | D11: < 40 | E11: <190 | F11: < 80 | G11: <310
B13: Infrastructure Projects | D13: (from Internet research and personal communication as of February 2026-- email suzanne@lucidtext.com with any updates and additions)
C14: Regional Center | D14: Project | E14: Categories | F14: I-956F approval status | G14: When fundraising | H14: EB-5 Investor Slots | I14: I-526E subscription status | J14: guess at slots filled by 2/2026 | K14: I-526E approvals? | L14: Link 1 | M14: Link 2 | N14: Link 3
C15: American Lending Center | D15: UAB Medical West Hospital | E15: infra only | F15: 45597 | G15: early 2025 | H15: =88/8 -> 11 | I15: full | J15: =88/8 -> 11 | L15: https://usa-rc.com/press-release/american-lending-center-wins-certification-of-public-infrastructure-projects-for-visa-set-asides/ | M15: https://usa-rc.com/portfolio/no-84-medical-west-hospital/
C16: American Lending Center | D16: Samaritan Hospital | E16: infra only | F16: 45597 | G16: early 2025 | H16: =40/8 -> 5 | I16: full | J16: =40/8 -> 5 | L16: https://usa-rc.com/press-release/american-lending-center-wins-certification-of-public-infrastructure-projects-for-visa-set-asides/ | M16: https://usa-rc.com/portfolio/no-97-samaritan-public-hospital/
C17: American Lending Center | D17: No. 98 Harrison Hospital Infrastructure | E17: infra only | F17: 45627 | G17: early 2025 | H17: =104/8 -> 13 | I17: full | J17: =104/8 -> 13 | L17: https://www.businesswire.com/news/home/20241210605558/en/ALCs-Flexible-Financing-Approach-For-Rural-Hospital-Gets-Federal-Approval | M17: https://usa-rc.com/portfolio/no-98-harrison-county-community-hospital/
C18: Boston Regional Center | D18: Boston Suffolk Downs Redevelopment Project (US National Infrastructure Development Fund 2, LLC) | E18: Infrastructure & HUA | F18: 45674 | G18: 2024-2025 | H18: 57 | I18: Full | J18: 57 | K18: Yes | L18: https://www.sec.gov/Archives/edgar/data/2043439/000168316824007960/xslFormDX01/primary_doc.xml | M18: https://echelonseaport.com/ | N18: https://www.eb5-project.com/sfdowns | O18: http://www.e-min.co.kr/iminnews2020-2.asp?mnu_code=001&board_code=001&b_serl=5631
C19: New England Regional Center | D19: Boston Bunker Hill Public Housing Redevelopment (US National Infrastructure Development Fund 4, LLC) | E19: Infrastructure Only | F19: Sept-2025 | G19: 2025-2026 | H19: 127 | J19: 127 | K19: Yes | L19: https://www.eb5-project.com/bunkerhill | M19: http://www.e-min.co.kr/iminnews2020-2.asp?mnu_code=001&board_code=001&b_serl=5609 | N19: https://mp.weixin.qq.com/s/rJpO_SZq9p3CAfj9eB_rHA
C20: New England Regional Center | D20: Boston Bunker Hill Public Housing Redevelopment (US National Infrastructure Development Fund 5, LLC) | E20: Infrastructure Only | G20: 2026 | H20: 312 | J20: 150 | L20: https://www.eb5-project.com/bunkerhill2
C21: Behring | D21: Community Investment for Veterans’ Infrastructure and Care (“CIVIC”) Project | E21: infra & HUA | F21: 45838 | G21: late 2025 | H21: 32 | I21: full | J21: 32 | K21: 7 as of 11/2025 | L21: https://behringeb5.com/civic-eb5-project-956f-approved-infrastructure-designation/ | M21: https://behringeb5.com/civic-i526e-approvals/
C22: Behring | D22: CIVIC amendment | E22: infra & HUA | F22: 46129 | G22: 2026 | H22: =52-32 -> 20 | L22: https://behringeb5.com/uscis-approves-i956f-amendment-civic-1950-franklin/
C23: EB5 Group | D23: Brainerd CBOC (MN) | E23: infra & Rural | F23: 46014 | G23: 2025 | H23: 54 | I23: full | J23: 54 | L23: https://www.eb5group.com/ | M23: https://www.linkedin.com/posts/activity-7422356548976480256-ui9A?utm_source=share&utm_medium=member_desktop&rcm=ACoAAAWNJowBHB6o6iZGhL9Y9yDp6S82Tv_mNzg
C24: USIF | D24: Grand Central Rising | E24: infra & HUA | F24: pending | G24: 2026 | H24: 437 | L24: https://visaeb-5.com/project/grand-central-rising/
C25: EB5 Group | D25: VA Outpatient Clinic, Round Rock | E25: infra only | F25: pending | G25: early 2026 | H25: =560/8 -> 70 | L25: note to check: I-956F NOID?
C26: CanAm | D26: Pacific Port Logistics Center, California | E26: infra & HUA | F26: pending (filed 2/2026) | G26: early 2026 | H26: 225 | J26: 80
C27: EB5 Group | D27: Virginia Beach CBOC | E27: infra only | F27: to be filed | G27: late 2026 | H27: 175
C28: EB5 Group | D28: Salt Lake CBOC | E28: infra only | F28: to be filed | G28: late 2026 | H28: 95
L29: Guess at 2025 Infrastructure Project distribution by country
H30: Slots | J30: Investors | M30: Receipts | N30: Approvals
G31: Estimated total by 2025 end | H31: =SUM(H15:H23) -> 631 | J31: =SUM(J15:J28) -> 529 | L31: China | M31: =$M$34*O31 -> 211.6 | N31: 30 | O31: 0.4
G32: Estimated total by 2026 end | H32: =SUM(H15:H28) -> 1633 | L32: India | M32: =$M$34*O32 -> 105.8 | N32: 20 | O32: 0.2
C33: Not Infrastructure projects | L33: ROW | M33: =$M$34*O33 -> 211.6 | N33: 80 | O33: 0.4
C34: Regional Center | D34: Project | E34: Categories | L34: Total | M34: =J31 -> 529 | N34: =SUM(N31:N33) -> 130 | O34: =SUM(O31:O33) -> 1
C35: EB5 United | D35: Texas Infrastructure Holdings, Uvalde | E35: HUA, Rural | L35: (this is a total guess -- replace with your best guess!)
C36: CanAm | D36: 360 Broadband, TX | E36: Rural only
C37: CanAm | D37: Green Hydrogen Plant Infrastructure Expansion | E37: High Unemployment
C38: CMB | D38: Group 101 | E38: High Unemployment
B41: Form I-485, Application to Register Permanent Residence or Adjust Status
B42: Pending Application for Employment-Based Preference Categories
B43: As of May 5, 2025
...

Sheet Progress
B1: Data related to progress in issuing Reserved visas, and advancing pipeline applicants to the visa stage
B3: Post-RIA Petition Filings and Adjudications
B4: http://www.uscis.gov/tools/reports-studies/immigration-forms-data
B5: Date | C5: I-956F Approved | D5: I-526/I-526E Filed | E5: I-526/I-526E Approved | F5: I-526/I-526E Denied | G5: Total Post-RIA I-526/I-526E Processed | H5: Period-End Post-RIA I-526/I-526E Pending | I5: Period-end Net Backlog
B6: 2022 Q3 Apr - Jun 2022 | D6: 32 | G6: 0
B7: 2022 Q4 Jul - Sep 2022 | D7: 188 | G7: 0
B8: 2023 Q1 Oct - Dec 2022 | D8: 453 | G8: 0
B9: 2023 Q2 Jan - Mar 2023 | C9: D | D9: 535 | G9: 0 | H9: 1127
B10: 2023 Q3 Apr - Jun 2023 | C10: D | D10: 699 | G10: 0 | H10: 1761
B11: 2023 Q4 Jul - Sep 2023 | C11: D | D11: 945 | E11: 63 | G11: 63 | H11: 2431
B12: 2024 Q1 Oct - Dec 2023 | C12: H | D12: 613 | E12: 194 | G12: 194 | H12: 2667
B13: 2024 Q2 Jan - Mar 2024 | C13: 60 | D13: 1879 | E13: H | F13: D | G13: 172 | H13: 3672
B14: 2024 Q3 Apr - Jun 2024 | C14: 88 | D14: 264 | E14: H | F14: D | G14: 332 | H14: 4685
B15: 2024 Q4 Jul - Sep 2024 | C15: 94 | D15: 1081 | E15: 396 | F15: 25 | G15: 421 | H15: 5850
B16: 2025 Q1 Oct - Dec 2024 | C16: 30 | D16: 1422 | E16: 267 | F16: 18 | G16: 303 | H16: 6924
B17: 2025 Q2 Jan - Mar 2025 | C17: H | D17: 1918 | E17: 208 | F17: 11 | G17: 219 | H17: 8856
B18: 2025 Q3 Apr - Jun 2025 | C18: 37 | D18: 1739 | E18: 1047 | F18: 66 | G18: 1113 | H18: 9539
B19: 2025 Q4 Jul - Sep 2025 | C19: 61 | D19: 1569 | E19: 1349 | F19: 81 | G19: 1430 | H19: 9669 | I19: 6400
B20: 2026 Q1 Oct - Dec 2025 | C20: 39 | D20: 1765 | E20: 764 | F20: 176 | G20: 940 | H20: 10470 | I20: 7300
B21: 2026 Q2 Jan - Mar 2026 | C21: 47 | D21: 1772 | E21: 781 | F21: 199 | G21: 980 | H21: 11229 | I21: 7900
C22: =SUM(C18:C21) -> 184 | D22: =SUM(D6:D21) -> 16874 | E22: =SUM(E6:E21) -> 5069 | F22: =SUM(F6:F21) -> 576 | G22: =SUM(G6:G21) -> 6167
B25: I-526/I-526E Receipts, Approvals, and Denials April 1, 2022 to January 31, 2025
B26: AIIA January 2025 FOIA
B27: https://goaiia.org/aiia-foia-series-updated-i-526e-inventory-statistics-for-january-2025/
D29: I-526/I-526E completions 2022 to Jan 31, 2025
C30: Receipts | D30: Approvals | E30: Denials | F30: Total Adjudicated | G30: % Total Adjudicated | H30: % of Receipts Adjudicated as of 1/25
B31: High Unemployment Area | C31: 5191 | D31: 351 | E31: 10 | F31: =SUM(D31:E31) -> 361 | G31: =F31/$F$36 -> 0.22848101 | H31: =F31/C31 -> 0.069543441
B32: Rural | C32: 4329 | D32: 1126 | E32: 30 | F32: =SUM(D32:E32) -> 1156 | G32: =F32/$F$36 -> 0.73164557 | H32: =F32/C32 -> 0.26703627
B33: Rural and HUA | D33: 7 | E33: 0 | F33: =SUM(D33:E33) -> 7 | G33: =F33/$F$36 -> 0.0044303797
B34: Infrastructure | D34: 0 | E34: 0 | F34: 0 | G34: =F34/$F$36 -> 0
B35: Unreserved and Unknown | D35: 35 | E35: 21 | F35: =SUM(D35:E35) -> 56 | G35: =F35/$F$36 -> 0.035443038
B36: Total All Categories | D36: =SUM(D31:D35) -> 1519 | E36: =SUM(E31:E35) -> 61 | F36: =SUM(F31:F35) -> 1580 | G36: =F36/$F$36 -> 1
B38: I-526/I-526E Receipts, Approvals, and Denials April 1, 2022 to July 31, 2025, by TEA category
B39: AIIA July 2025 FOIA
B40: https://goaiia.org/blog/aiia-foia-series-updated-i-526e-inventory-statistics-for-july-2025/#
C41: Receipts | D41: Approvals | E41: Denials | F41: Total Adjudicated | G41: % Total Adjudicated | H41: % of Receipts Adjudicated as of 7/25 | W41: Data Source: https://travel.state.gov/content/travel/en/legal/visa-law0/visa-statistics/immigrant-visa-statistics/monthly-immigrant-visa-issuances.html
B42: High Unemployment Area | C42: 6582 | D42: 545 | E42: 13 | F42: =SUM(D42:E42) -> 558 | G42: =F42/$F$47 -> 0.15696203 | H42: =F42/C42 -> 0.084776664
B43: Rural Area | C43: 6406 | D43: 2819 | E43: 62 | F43: =SUM(D43:E43) -> 2881 | G43: =F43/$F$47 -> 0.81040788 | H43: =F43/C43 -> 0.44973462 | W43: Data Source: http://www.uscis.gov/tools/reports-studies/immigration-forms-data
B44: Rural Area and HUA | C44: 99 | D44: 29 | E44: 1 | F44: =SUM(D44:E44) -> 30 | G44: =F44/$F$47 -> 0.0084388186
B45: Infrastructure | C45: 0 | D45: 0 | E45: 0 | F45: =SUM(D45:E45) -> 0 | G45: =F45/$F$47 -> 0
...

Sheet Visa Supply
B1: EB-5 Visa Supply Projection 1 -- Scenario with significant FB rollover usage | M1: EB-5 Visa Supply Projection 2 -- scenario with minimal FB rollover | Z1: References
B3: Last updated: | C3: 46118 | M3: Last updated: | N3: 46118 | Z3: https://www.canamenterprises.com/about-eb-5/faq/
Z4: https://www.canamenterprises.com/2025/08/13/white-paper-2025-visa-backlog/
B5: Summary: Estimated Total EB-5 Visas | M5: Summary: Estimated Total EB-5 Visas | Z5: https://travel.state.gov/content/travel/en/legal/visa-law0/visa-statistics/immigrant-visa-statistics.html
B6: EB-5 visas available in theory | C6: Actual | D6: Actual | E6: Actual | F6: Actual | G6: Estimate | H6: Estimate | I6: Estimate | J6: Estimate | M6: EB-5 visas available in theory | N6: Actual | O6: Actual | P6: Actual | Q6: Estimate | R6: Estimate | S6: Estimate | T6: Estimate | U6: Estimate | Z6: https://blog.lucidtext.com/ina-203b/#b-designations-and-reserved-visas
C7: 2022 | D7: 2023 | E7: 2024 | F7: 2025 | G7: 2026 | H7: 2027 | I7: 2028 | J7: 2029 | N7: 2022 | O7: 2023 | P7: 2024 | Q7: 2025 | R7: 2026 | S7: 2027 | T7: 2028 | U7: 2029
B8: Unreserved | C8: =C64 -> 13591.158 | D8: =D64 -> 9515.5535 | E8: =E64 -> 14207.109 | F8: =F64 -> 11298.694 | G8: =G64 -> 9655.9715 | H8: =H64 -> 9964.8406 | I8: =I64 -> 9656 | J8: =J64 -> 6759.2 | M8: Unreserved | N8: =N64 -> 13591.158 | O8: =O64 -> 9515.5535 | P8: =P64 -> 14207.109 | Q8: =Q64 -> 11298.694 | R8: =R64 -> 9671.6142 | S8: =S64 -> 7550.8406 | T8: =T64 -> 6759.2 | U8: =U64 -> 6759.2
B9: Rural | C9: =C48 -> 3997.3994 | D9: =D48 -> 6796.0916 | E9: =E48 -> 5096.1244 | F9: =F48 -> 4427.9576 | G9: =G48 -> 4771 | H9: =H48 -> 5481.2 | I9: =I48 -> 2982.2 | J9: =J48 -> 2229.7 | M9: Rural | N9: =N48 -> 3997.3994 | O9: =O48 -> 6796.0916 | P9: =P48 -> 5096.1244 | Q9: =Q48 -> 4427.9576 | R9: =R48 -> 4776 | S9: =S48 -> 4775.8008 | T9: =T48 -> 2503.8008 | U9: =U48 -> 2503.8008
B10: High Unemployment | C10: =C51 -> 1998.6997 | D10: =D51 -> 3398.0458 | E10: =E51 -> 2548.0622 | F10: =F51 -> 2213.9788 | G10: =G51 -> 2385.8627 | H10: =H51 -> 2740.6 | I10: =I51 -> 1490.6 | J10: =J51 -> 1114.6 | M10: High Unemployment | N10: =N51 -> 1998.6997 | O10: =O51 -> 3398.0458 | P10: =P51 -> 2548.0622 | Q10: =Q51 -> 2213.9788 | R10: =R51 -> 2388.1631 | S10: =S51 -> 2387.9004 | T10: =T51 -> 1251.9004 | U10: =U51 -> 1251.9004
B11: Infrastructure | C11: =C54 -> 399.73994 | D11: =D54 -> 679.60916 | E11: =E54 -> 509.61244 | F11: =F54 -> 442.79576 | G11: =G54 -> 477.17254 | H11: =H54 -> 548.12 | I11: =I54 -> 298.12 | J11: =J54 -> 222.92 | M11: Infrastructure | N11: =N54 -> 399.73994 | O11: =O54 -> 679.60916 | P11: =P54 -> 509.61244 | Q11: =Q54 -> 442.79576 | R11: =R54 -> 477.63262 | S11: =S54 -> 477.58008 | T11: =T54 -> 250.38008 | U11: =U54 -> 250.18008
B12: TOTAL Visas Available | C12: =SUM(C8:C11) -> 19986.997 | D12: =SUM(D8:D11) -> 20389.3 | E12: =SUM(E8:E11) -> 22360.908 | F12: =SUM(F8:F11) -> 18383.426 | G12: =SUM(G8:G11) -> 17290.007 | H12: =SUM(H8:H11) -> 18734.761 | I12: =SUM(I8:I11) -> 14426.92 | J12: =SUM(J8:J11) -> 10326.42 | M12: TOTAL Visas Available | N12: =SUM(N8:N11) -> 19986.997 | O12: =SUM(O8:O11) -> 20389.3 | P12: =SUM(P8:P11) -> 22360.908 | Q12: =SUM(Q8:Q11) -> 18383.426 | R12: =SUM(R8:R11) -> 17313.41 | S12: =SUM(S8:S11) -> 15192.122 | T12: =SUM(T8:T11) -> 10765.281 | U12: =SUM(U8:U11) -> 10765.081
B14: Estimated actual EB-5 visas issued (considering demand/processing constraints and carryover) | M14: Estimated actual EB-5 visas issued (considering demand/processing constraints and carryover)
C15: Actual | D15: Actual | E15: Actual | F15: Estimate | G15: Estimate | H15: Estimate | I15: Estimate | J15: Estimate | N15: Actual | O15: Actual | P15: Actual | Q15: Estimate | R15: Estimate | S15: Estimate | T15: Estimate | U15: Estimate
C16: 2022 | D16: 2023 | E16: 2024 | F16: 2025 | G16: 2026 | H16: 2027 | I16: 2028 | J16: 2029 | K16: Normal Year | N16: 2022 | O16: 2023 | P16: 2024 | Q16: 2025 | R16: 2026 | S16: 2027 | T16: 2028 | U16: 2029 | V16: Normal Year
B17: Unreserved | C17: 10885 | D17: 9817 | E17: 14501 | F17: =Progress!C152 -> 11470 | G17: =G64 -> 9655.9715 | H17: =H29 -> 9656 | I17: =I29 -> 9656 | J17: =J29 -> 6759.2 | K17: =K21*0.68 -> 6759.2 | M17: Unreserved | N17: 10885 | O17: 9817 | P17: 14501 | Q17: =Progress!C152 -> 11470 | R17: =R64 -> 9671.6142 | S17: =S29 -> 7242 | T17: =T29 -> 6759.2 | U17: =U29 -> 6759.2 | V17: =V21*0.68 -> 6759.2
B18: Rural | C18: =C36 -> 0 | D18: =D36 -> 0 | E18: 332 | F18: =F36 -> 2000 | G18: =G36 -> 2000 | H18: =H36 -> 5339 | I18: =I36 -> 2740.5 | J18: =J36 -> 2130 | K18: =K21*0.2 -> 1988 | M18: Rural | N18: =N36 -> 0 | O18: =O36 -> 0 | P18: 332 | Q18: =Q36 -> 2000 | R18: =R36 -> 2000 | S18: =S36 -> 4260 | T18: =T36 -> 1988 | U18: =U36 -> 1988 | V18: =V21*0.2 -> 1988
B19: High Unemployment | C19: =C38 -> 0 | D19: =D38 -> 0 | E19: 91 | F19: =F38 -> 1000 | G19: =G38 -> 1000 | H19: =H38 -> 2670 | I19: =I38 -> 1370 | J19: =J38 -> 1150 | K19: =K21*0.1 -> 994 | M19: High Unemployment | N19: =N38 -> 0 | O19: =O38 -> 0 | P19: 91 | Q19: =Q38 -> 1000 | R19: =R38 -> 1000 | S19: =S38 -> 2130 | T19: =T38 -> 994 | U19: =U38 -> 994 | V19: =V21*0.1 -> 994
B20: Infrastructure | C20: =C40 -> 0 | D20: =D40 -> 0 | E20: =E40 -> 0 | F20: =F40 -> 0 | G20: =G40 -> 100 | H20: =H40 -> 534 | I20: =I40 -> 274 | J20: =J40 -> 230 | K20: =K21*0.02 -> 198.8 | M20: Infrastructure | N20: =N40 -> 0 | O20: =O40 -> 0 | P20: =P40 -> 0 | Q20: =Q40 -> 0 | R20: =R40 -> 100 | S20: =S40 -> 426 | T20: =T40 -> 199 | U20: =U40 -> 199 | V20: =V21*0.02 -> 198.8
B21: TOTAL Visas Issued | C21: =SUM(C17:C20) -> 10885 | D21: =SUM(D17:D20) -> 9817 | E21: =SUM(E17:E20) -> 14924 | F21: =SUM(F17:F20) -> 14470 | G21: =SUM(G17:G20) -> 12755.972 | H21: =SUM(H17:H20) -> 18199 | I21: =SUM(I17:I20) -> 14040.5 | J21: =SUM(J17:J20) -> 10269.2 | K21: =140000*0.071 -> 9940 | M21: TOTAL Visas Issued | N21: =SUM(N17:N20) -> 10885 | O21: =SUM(O17:O20) -> 9817 | P21: =SUM(P17:P20) -> 14924 | Q21: =SUM(Q17:Q20) -> 14470 | R21: =SUM(R17:R20) -> 12771.614 | S21: =SUM(S17:S20) -> 14058 | T21: =SUM(T17:T20) -> 9940.2 | U21: =SUM(U17:U20) -> 9940.2 | V21: =140000*0.071 -> 9940
B23: Derivation of visa number estimates, including carryover | M23: Derivation of visa number estimates, including carryover
H24: Cells with input guesses -- ACTUAL VALUES COULD VARY | S24: Cells with input guesses -- ACTUAL VALUES COULD VARY
B25: New issue visas available | M25: New issue visas available
B26: Annual Limits (newly available pool) | C26: 2022 | D26: 2023 | E26: 2024 | F26: 2025 | G26: 2026 | H26: 2027 | I26: 2028 | J26: 2029 | M26: Annual Limits (newly available pool) | N26: 2022 | O26: 2023 | P26: 2024 | Q26: 2025 | R26: 2026 | S26: 2027 | T26: 2028 | U26: 2029
B27: Worldwide Employment Limit | C27: 281507 | D27: 197091 | E27: 161791 | F27: 150037 | G27: 186000 | H27: =140000+60000 -> 200000 | I27: 200000 | J27: 140000 | M27: Worldwide Employment Limit | N27: 281507 | O27: 197091 | P27: 161791 | Q27: 150037 | R27: 186324 | S27: 150000 | T27: 140000 | U27: 140000
B28: EB-5 Newly-Available Pool (7.1%) | C28: =C27*0.071 -> 19986.997 | D28: =D27*0.071 -> 13993.461 | E28: =E27*0.071 -> 11487.161 | F28: =F27*0.071 -> 10652.627 | G28: =G27*0.071 -> 13206 | H28: =H27*0.071 -> 14200 | I28: =I27*0.071 -> 14200 | J28: =J27*0.071 -> 9940 | M28: EB-5 Newly-Available Pool (7.1%) | N28: =N27*0.071 -> 19986.997 | O28: =O27*0.071 -> 13993.461 | P28: =P27*0.071 -> 11487.161 | Q28: =Q27*0.071 -> 10652.627 | R28: =R27*0.071 -> 13229.004 | S28: =S27*0.071 -> 10650 | T28: =T27*0.071 -> 9940 | U28: =U27*0.071 -> 9940
B29: Unreserved (68%) | C29: =C28*0.68 -> 13591.158 | D29: =D28*0.68 -> 9515.5535 | E29: =E28*0.68 -> 7811.2695 | F29: =F28*0.68 -> 7243.7864 | G29: =G28*0.68 -> 8980.08 | H29: =H28*0.68 -> 9656 | I29: =I28*0.68 -> 9656 | J29: =J28*0.68 -> 6759.2 | M29: Unreserved (68%) | N29: =N28*0.68 -> 13591.158 | O29: =O28*0.68 -> 9515.5535 | P29: =P28*0.68 -> 7811.2695 | Q29: =Q28*0.68 -> 7243.7864 | R29: =R28*0.68 -> 8995.7227 | S29: =S28*0.68 -> 7242 | T29: =T28*0.68 -> 6759.2 | U29: =U28*0.68 -> 6759.2
B30: Rural (20%) | C30: =C28*0.2 -> 3997.3994 | D30: =D28*0.2 -> 2798.6922 | E30: =E28*0.2 -> 2297.4322 | F30: =F28*0.2 -> 2130.5254 | G30: =G28*0.2 -> 2641.2 | H30: =H28*0.2 -> 2840 | I30: =I28*0.2 -> 2840 | J30: =J28*0.2 -> 1988 | M30: Rural (20%) | N30: =N28*0.2 -> 3997.3994 | O30: =O28*0.2 -> 2798.6922 | P30: =P28*0.2 -> 2297.4322 | Q30: =Q28*0.2 -> 2130.5254 | R30: =R28*0.2 -> 2645.8008 | S30: =S28*0.2 -> 2130 | T30: =T28*0.2 -> 1988 | U30: =U28*0.2 -> 1988
B31: High Unemployment (10%) | C31: =C28*0.1 -> 1998.6997 | D31: =D28*0.1 -> 1399.3461 | E31: =E28*0.1 -> 1148.7161 | F31: =F28*0.1 -> 1065.2627 | G31: =G28*0.1 -> 1320.6 | H31: =H28*0.1 -> 1420 | I31: =I28*0.1 -> 1420 | J31: =J28*0.1 -> 994 | M31: High Unemployment (10%) | N31: =N28*0.1 -> 1998.6997 | O31: =O28*0.1 -> 1399.3461 | P31: =P28*0.1 -> 1148.7161 | Q31: =Q28*0.1 -> 1065.2627 | R31: =R28*0.1 -> 1322.9004 | S31: =S28*0.1 -> 1065 | T31: =T28*0.1 -> 994 | U31: =U28*0.1 -> 994
B32: Infrastructure (2%) | C32: =C28*0.02 -> 399.73994 | D32: =D28*0.02 -> 279.86922 | E32: =E28*0.02 -> 229.74322 | F32: =F28*0.02 -> 213.05254 | G32: =G28*0.02 -> 264.12 | H32: =H28*0.02 -> 284 | I32: =I28*0.02 -> 284 | J32: =J28*0.02 -> 198.8 | M32: Infrastructure (2%) | N32: =N28*0.02 -> 399.73994 | O32: =O28*0.02 -> 279.86922 | P32: =P28*0.02 -> 229.74322 | Q32: =Q28*0.02 -> 213.05254 | R32: =R28*0.02 -> 264.58008 | S32: =S28*0.02 -> 213 | T32: =T28*0.02 -> 198.8 | U32: =U28*0.02 -> 198.8
F33: =SUM(F30:F32) -> 3408.8406 | Q33: =SUM(Q30:Q32) -> 3408.8406
B34: Assumptions affecting carryover | M34: Assumptions affecting carryover
B35: Enter Usage Guesses | C35: 2022 | D35: 2023 | E35: 2024 | F35: 2025 | G35: 2026 | H35: 2027 | I35: 2028 | J35: 2029 | M35: Enter Usage Guesses | N35: 2022 | O35: 2023 | P35: 2024 | Q35: 2025 | R35: 2026 | S35: 2027 | T35: 2028 | U35: 2029
B36: Rural visas issued | C36: 0 | D36: 0 | E36: 332 | F36: =ROUNDUP(Progress!J120,-3) -> 2000 | G36: 2000 | H36: 5339 | I36: 2740.5 | J36: 2130 | M36: Rural visas issued | N36: 0 | O36: 0 | P36: 332 | Q36: =F36 -> 2000 | R36: 2000 | S36: 4260 | T36: 1988 | U36: 1988
B37: issued ≤ availability? | F37: =IF(F36<=F48,"yes","NO") -> yes | G37: =IF(G36<=G48,"yes","NO") -> yes | H37: =IF(H36<=H48,"yes","NO") -> yes | I37: =IF(I36<=I48,"yes","NO") -> yes | J37: =IF(J36<=J48,"yes","NO") -> yes | M37: issued ≤ availability? | Q37: =IF(Q36<=Q48,"yes","NO") -> yes | R37: =IF(R36<=R48,"yes","NO") -> yes | S37: =IF(S36<=S48,"yes","NO") -> yes | T37: =IF(T36<=T48,"yes","NO") -> yes | U37: =IF(U36<=U48,"yes","NO") -> yes
B38: HU visas issued | C38: 0 | D38: 0 | E38: 91 | F38: =ROUNDUP(Progress!J128,-3) -> 1000 | G38: 1000 | H38: 2670 | I38: 1370 | J38: 1150 | M38: HU visas issued | N38: 0 | O38: 0 | P38: 91 | Q38: =F38 -> 1000 | R38: 1000 | S38: 2130 | T38: 994 | U38: 994
B39: issued ≤ availability? | F39: =IF(F38<=F51,"yes","NO") -> yes | G39: =IF(G38<=G51,"yes","NO") -> yes | H39: =IF(H38<=H51,"yes","NO") -> yes | I39: =IF(I38<=I51,"yes","NO") -> yes | J39: =IF(J38<=J51,"yes","NO") -> NO | M39: issued ≤ availability? | Q39: =IF(Q38<=Q51,"yes","NO") -> yes | R39: =IF(R38<=R51,"yes","NO") -> yes | S39: =IF(S38<=S51,"yes","NO") -> yes | T39: =IF(T38<=T51,"yes","NO") -> yes | U39: =IF(U38<=U51,"yes","NO") -> yes
B40: Infrastructure visas issued | C40: 0 | D40: 0 | E40: 0 | F40: 0 | G40: 100 | H40: 534 | I40: 274 | J40: 230 | M40: Infrastructure visas issued | N40: 0 | O40: 0 | P40: 0 | Q40: 0 | R40: 100 | S40: 426 | T40: 199 | U40: 199
B41: issued ≤ availability? | F41: =IF(F40<=F54,"yes","NO") -> yes | G41: =IF(G40<=G54,"yes","NO") -> yes | H41: =IF(H40<=H54,"yes","NO") -> yes | I41: =IF(I40<=I54,"yes","NO") -> yes | J41: =IF(J40<=J54,"yes","NO") -> NO | M41: issued ≤ availability? | Q41: =IF(Q40<=Q54,"yes","NO") -> yes | R41: =IF(R40<=R54,"yes","NO") -> yes | S41: =IF(S40<=S54,"yes","NO") -> yes | T41: =IF(T40<=T54,"yes","NO") -> yes | U41: =IF(U40<=U54,"yes","NO") -> yes
B42: Total reserved visas issued | C42: =SUM(C36:C40) -> 0 | D42: =SUM(D36:D40) -> 0 | E42: =SUM(E36:E40) -> 423 | F42: =SUM(F36:F40) -> 3000 | G42: =SUM(G36:G40) -> 3100 | H42: =SUM(H36:H40) -> 8543 | I42: =SUM(I36:I40) -> 4384.5 | J42: =SUM(J36:J40) -> 3510 | M42: Total reserved visas issued | N42: =SUM(N36:N40) -> 0 | O42: =SUM(O36:O40) -> 0 | P42: =SUM(P36:P40) -> 423 | Q42: =SUM(Q36:Q40) -> 3000 | R42: =SUM(R36:R40) -> 3100 | S42: =SUM(S36:S40) -> 6816 | T42: =SUM(T36:T40) -> 3181 | U42: =SUM(U36:U40) -> 3181
B44: Calculate total EB-5 visas available with carryover | M44: Calculate total EB-5 visas available with carryover
...

Sheet Pre-RIA China
B1: Visa Timing ESTIMATE -- CHINA Unreserved
B3: Background
B4: Estimated total Pre-RIA EB-5 Unreserved pipeline backlog
C5: China | D5: India | E5: ROW | F5: Total
B6: as of June 2025
C8: 0.4 | D8: Average pre-RIA I-526 approval rate in 2024 for China
C9: 2.5359256 | D9: Average visas per investor applicant in 2021-2023 (worldwide, AOS+consular)
C11: China | D11: China
B12: Visa Bulletin | C12: Chart A | D12: Chart B
B13: 44835 | C13: 42085 | D13: 42370
B14: 45200 | C14: 42278 | D14: 42736
B15: 45566 | C15: 42566 | D15: 42644
B16: 45931 | C16: 42346 | D16: 42552
B18: Unreserved China VISA DEMAND ESTIMATE as of June 2024 | G18: =C8*C9 -> 1.0143702 | M18: Unreserved VISA SUPPLY ESTIMATE from June 2024
E19: A | F19: B | G19: C | H19: D=A+B+C | I19: E | K19: MATCH DEMAND to SUPPLY | N19: A | O19: B | P19: C | Q19: D | R19: E | S19: F=A-B-C-D-E
B20: Priority Date | C20: I-526 Filed (actual until 10/2020, estimate for 2021-2022) | D20: I-526 Pending as of 7/2024 (actual) | E20: Applicants registered at NVC as of 5/2024 (quarterly estimate from actual annual) | F20: I-485 Pending as of 6/2024 (actual) | G20: Estimate of future visa applicants from pending I-526 as of 7/2024 | H20: Estimated Total Visa Applicants as of June 2024 | I20: Estimated Cumulative Visa Applicants | J20: Visa availability per Oct 24 Visa Bulletin | K20: Date of visa availability per supply-demand ESTIMATE | M20: Date of visa issuance | N20: Total Unreserved visas (est.) | O20: Visas issued to Pre-RIA India up to cap | P20: Visas issued to Post-RIA India up to cap | Q20: Estimated visas issued to Pre-RIA ROW | R20: Post-RIA ROW (GUESS)* | S20: Estimated total visas issued to Pre-RIA China | T20: Cumulative Total to China
B21: Pre-2015 | D21: 6 | E21: 588 | F21: 0 | G21: =D21*G$18 -> 6.0862215 | H21: =SUM(E21:G21) -> 594.08622 | I21: =H21 -> 594.08622 | J21: current | K21: =_xlfn.XLOOKUP(I21,$T$22:$T$30,$U$22:$U$30,"FY25 and earlier",-1) -> FY25 and earlier | M21: 2024 June-Sept | O21: 130 | Q21: 1300 | S21: 4470 | T21: =S21 -> 4470
B22: 2015 Q1. Oct - Dec 2014 | C22: 2783.0277 | D22: 1 | F22: 0 | G22: =D22*G$18 -> 1.0143702 | H22: =SUM(E22:G22) -> 1.0143702 | I22: =H22+I21 -> 595.10059 | J22: current | K22: =_xlfn.XLOOKUP(I22,$T$22:$T$30,$U$22:$U$30,"FY25 and earlier",-1) -> FY25 and earlier | M22: FY2025 | N22: 11469.908 | O22: =N22*0.07 -> 802.89353 | Q22: 5000 | R22: 50 | S22: =N22-O22-P22-Q22-R22 -> 5617.014 | T22: =T21+S22 -> 10087.014 | U22: FY2025
B23: 2015 Q2. Jan - Mar 2015 | C23: 2184.9748 | D23: 1 | E23: 1286.518 | F23: 0 | G23: =D23*G$18 -> 1.0143702 | H23: =SUM(E23:G23) -> 1287.5324 | I23: =H23+I22 -> 1882.633 | J23: current | K23: =_xlfn.XLOOKUP(I23,$T$22:$T$30,$U$22:$U$30,"FY25 and earlier",-1) -> FY25 and earlier | M23: FY2026 | N23: 12000 | O23: =N23*0.07 -> 840 | Q23: 3300 | R23: 700 | S23: =N23-O23-P23-Q23-R23 -> 7160 | T23: =T22+S23 -> 17247.014 | U23: FY2026
B24: 2015 Q3 Apr - Jun 2015 | C24: 2340.1658 | D24: 3 | E24: 1377.8948 | F24: 14 | G24: =D24*G$18 -> 3.0431107 | H24: =SUM(E24:G24) -> 1394.9379 | I24: =H24+I23 -> 3277.5709 | J24: current | K24: =_xlfn.XLOOKUP(I24,$T$22:$T$30,$U$22:$U$30,"FY25 and earlier",-1) -> FY25 and earlier | M24: FY2027 | N24: 10000 | O24: =N24*0.07 -> 700 | R24: 3500 | S24: =N24-O24-P24-Q24-R24 -> 5800 | T24: =T23+S24 -> 23047.014 | U24: FY2027
B25: 2015 Q4 Jul - Sep 2015 | C25: 6221.8317 | D25: 28 | E25: 3663.4283 | F25: 89 | G25: =D25*G$18 -> 28.402367 | H25: =SUM(E25:G25) -> 3780.8307 | I25: =H25+I24 -> 7058.4016 | J25: current | K25: =_xlfn.XLOOKUP(I25,$T$22:$T$30,$U$22:$U$30,"FY25 and earlier",-1) -> FY25 and earlier | M25: FY2028 | N25: 6800 | O25: =N25*0.07 -> 476 | R25: 3500 | S25: =N25-O25-P25-Q25-R25 -> 2824 | T25: =T24+S25 -> 25871.014 | U25: FY2028
B26: 2016 Q1 Oct - Dec 2015 | C26: 3808 | D26: 33 | E26: 2242.1589 | F26: 118 | G26: =D26*G$18 -> 33.474218 | H26: =SUM(E26:G26) -> 2393.6331 | I26: =H26+I25 -> 9452.0347 | J26: current | K26: =_xlfn.XLOOKUP(I26,$T$22:$T$30,$U$22:$U$30,"FY25 and earlier",-1) -> FY25 and earlier | M26: FY2029 | N26: 6800 | O26: =N26*0.07 -> 476 | R26: =R25 -> 3500 | S26: =N26-O26-P26-Q26-R26 -> 2824 | T26: =T25+S26 -> 28695.014 | U26: FY2029
B27: 2016 Q2 Jan - Mar 2016 | C27: 391 | D27: 4 | E27: 545.90335 | F27: 98 | G27: =D27*G$18 -> 4.057481 | H27: =SUM(E27:G27) -> 647.96083 | I27: =H27+I26 -> 10099.995 | J27: current | K27: =_xlfn.XLOOKUP(I27,$T$22:$T$30,$U$22:$U$30,"FY25 and earlier",-1) -> FY2025 | M27: FY2030 | N27: 6800 | O27: 363 | P27: 113 | R27: =R26 -> 3500 | S27: =N27-O27-P27-Q27-R27 -> 2824 | T27: =T26+S27 -> 31519.014 | U27: FY2030
B28: 2016 Q3 April - June 2016 | C28: 1415 | D28: 20 | E28: 1975.5837 | F28: 332 | G28: =D28*G$18 -> 20.287405 | H28: =SUM(E28:G28) -> 2327.8711 | I28: =H28+I27 -> 12427.867 | J28: current | K28: =_xlfn.XLOOKUP(I28,$T$22:$T$30,$U$22:$U$30,"FY25 and earlier",-1) -> FY2025 | M28: FY2031 | N28: 6800 | P28: =N28*0.07 -> 476 | R28: =R27 -> 3500 | S28: =N28-O28-P28-Q28-R28 -> 2824 | T28: =T27+S28 -> 34343.014 | U28: FY2031
B29: 2016 Q4 Jul - Sep 2016 | C29: 5334 | D29: 79 | E29: 7447.1828 | F29: 1165 | G29: =D29*G$18 -> 80.135249 | H29: =SUM(E29:G29) -> 8692.318 | I29: =H29+I28 -> 21120.185 | J29: 2025/2026 | K29: =_xlfn.XLOOKUP(I29,$T$22:$T$30,$U$22:$U$30,"FY25 and earlier",-1) -> FY2026 | M29: FY2032 | N29: 6800 | P29: =N29*0.07 -> 476 | R29: =R28 -> 3500 | S29: =N29-O29-P29-Q29-R29 -> 2824 | T29: =T28+S29 -> 37167.014 | U29: FY2032
B30: 2017 Q1 Oct - Dec 2016 | C30: 3310 | D30: 87 | E30: 4621.3301 | F30: 782 | G30: =D30*G$18 -> 88.250211 | H30: =SUM(E30:G30) -> 5491.5804 | I30: =H30+I29 -> 26611.765 | K30: =_xlfn.XLOOKUP(I30,$T$22:$T$30,$U$22:$U$30,"FY25 and earlier",-1) -> FY2028 | M30: FY2033 | N30: 6800 | P30: =N30*0.07 -> 476 | R30: =R29 -> 3500 | S30: =N30-O30-P30-Q30-R30 -> 2824 | T30: =T29+S30 -> 39991.014 | U30: FY2033
B31: 2017 Q2. Jan - Mar 2017 | C31: 1172 | D31: 94 | E31: 1198.9144 | F31: 0 | G31: =D31*G$18 -> 95.350803 | H31: =SUM(E31:G31) -> 1294.2652 | I31: =H31+I30 -> 27906.03 | K31: =_xlfn.XLOOKUP(I31,$T$22:$T$30,$U$22:$U$30,"FY25 and earlier",-1) -> FY2028 | M31: Total | O31: =SUM(O21:O30) -> 3787.8935 | Q31: =SUM(Q21:Q30) -> 9600
B32: 2017 Q3. April - June 2017 | C32: 3280 | D32: 430 | E32: 3355.3236 | F32: 0 | G32: =D32*G$18 -> 436.17921 | H32: =SUM(E32:G32) -> 3791.5028 | I32: =H32+I31 -> 31697.533 | K32: =_xlfn.XLOOKUP(I32,$T$22:$T$30,$U$22:$U$30,"FY25 and earlier",-1) -> FY2030 | O32: =D6 | Q32: =E6
B33: 2017 Q4 Jul - Sep 2017 | C33: 1009 | D33: 243 | E33: 1032.1712 | F33: 0 | G33: =D33*G$18 -> 246.49197 | H33: =SUM(E33:G33) -> 1278.6632 | I33: =H33+I32 -> 32976.196 | K33: =_xlfn.XLOOKUP(I33,$T$22:$T$30,$U$22:$U$30,"FY25 and earlier",-1) -> FY2030 | M33: *Guess assumes that post-RIA ROW applicants will increasingly choose to be assigned Unreserved visas
B34: 2018 Q1 Oct - Dec 2017 | C34: 1245 | D34: 326 | E34: 1273.5908 | F34: 0 | G34: =D34*G$18 -> 330.6847 | H34: =SUM(E34:G34) -> 1604.2755 | I34: =H34+I33 -> 34580.472 | K34: =_xlfn.XLOOKUP(I34,$T$22:$T$30,$U$22:$U$30,"FY25 and earlier",-1) -> FY2031 | M34: and that 2024 ROW demand was/will be typical
B35: 2018 Q2. Jan - Mar 2018 | C35: 696 | D35: 358 | E35: 302 | F35: 0 | G35: =D35*G$18 -> 363.14455 | H35: =SUM(E35:G35) -> 665.14455 | I35: =H35+I34 -> 35245.616 | K35: =_xlfn.XLOOKUP(I35,$T$22:$T$30,$U$22:$U$30,"FY25 and earlier",-1) -> FY2031 | M35: Estimated Status of Chinese investors with October 2014+ priority dates, as of October 2024
B36: 2018 Q3. April - June 2018 | C36: 207 | D36: 154 | E36: 89.818966 | F36: 0 | G36: =D36*G$18 -> 156.21302 | H36: =SUM(E36:G36) -> 246.03198 | I36: =H36+I35 -> 35491.648 | K36: =_xlfn.XLOOKUP(I36,$T$22:$T$30,$U$22:$U$30,"FY25 and earlier",-1) -> FY2031 | M36: Visas issued to date to China-born applicants with priority dates since Oct 2014*
B37: 2018 Q4 Jul - Sep 2018 | C37: 294 | D37: 277 | E37: 127.56897 | F37: 0 | G37: =D37*G$18 -> 280.98056 | H37: =SUM(E37:G37) -> 408.54952 | I37: =H37+I36 -> 35900.198 | K37: =_xlfn.XLOOKUP(I37,$T$22:$T$30,$U$22:$U$30,"FY25 and earlier",-1) -> FY2031 | R37: Year visa issued | S37: EB-5 Visas Issued to China
B38: 2019 Q1 Oct - Dec 2018 | C38: 195 | D38: 144 | E38: 84.612069 | F38: 0 | G38: =D38*G$18 -> 146.06932 | H38: =SUM(E38:G38) -> 230.68138 | I38: =H38+I37 -> 36130.879 | K38: =_xlfn.XLOOKUP(I38,$T$22:$T$30,$U$22:$U$30,"FY25 and earlier",-1) -> FY2031 | R38: FY2020 | S38: 1686
B39: 2019 Q2. Jan - Mar 2019 | C39: 118 | D39: 99 | E39: 0 | F39: 0 | G39: =D39*G$18 -> 100.42265 | H39: =SUM(E39:G39) -> 100.42265 | I39: =H39+I38 -> 36231.302 | K39: =_xlfn.XLOOKUP(I39,$T$22:$T$30,$U$22:$U$30,"FY25 and earlier",-1) -> FY2031 | R39: FY2021 | S39: 1567
B40: 2019 Q3. April - June 2019 | C40: 91 | D40: 80 | E40: 0 | F40: 0 | G40: =D40*G$18 -> 81.14962 | H40: =SUM(E40:G40) -> 81.14962 | I40: =H40+I39 -> 36312.451 | K40: =_xlfn.XLOOKUP(I40,$T$22:$T$30,$U$22:$U$30,"FY25 and earlier",-1) -> FY2031 | R40: FY2022 | S40: 6125
B41: 2019 Q4 Jul - Sep 2019 | C41: 118 | D41: 97 | E41: 0 | F41: 0 | G41: =D41*G$18 -> 98.393914 | H41: =SUM(E41:G41) -> 98.393914 | I41: =H41+I40 -> 36410.845 | K41: =_xlfn.XLOOKUP(I41,$T$22:$T$30,$U$22:$U$30,"FY25 and earlier",-1) -> FY2031 | R41: FY2023 | S41: 6262
B42: 2020 Q1 Oct - Dec 2019 | C42: 416 | D42: 369 | E42: 31 | F42: 0 | G42: =D42*G$18 -> 374.30262 | H42: =SUM(E42:G42) -> 405.30262 | I42: =H42+I41 -> 36816.148 | K42: =_xlfn.XLOOKUP(I42,$T$22:$T$30,$U$22:$U$30,"FY25 and earlier",-1) -> FY2031 | R42: FY2024 | S42: 9312
B43: 2020 Q2 Jan - Mar 2020 | C43: 3 | D43: 2 | E43: 0 | F43: 0 | G43: =D43*G$18 -> 2.0287405 | H43: =SUM(E43:G43) -> 2.0287405 | I43: =H43+I42 -> 36818.177 | K43: =_xlfn.XLOOKUP(I43,$T$22:$T$30,$U$22:$U$30,"FY25 and earlier",-1) -> FY2031 | S43: =SUM(S38:S42) -> 24952
B44: 2020 Q3 Apr - Jun 2020 | C44: 2 | D44: 2 | E44: 0 | F44: 0 | G44: =D44*G$18 -> 2.0287405 | H44: =SUM(E44:G44) -> 2.0287405 | I44: =H44+I43 -> 36820.205 | K44: =_xlfn.XLOOKUP(I44,$T$22:$T$30,$U$22:$U$30,"FY25 and earlier",-1) -> FY2031 | M44: *The Visa Bulletin first moved the China final action date past Oct 1, 2014 at the end of FY2019 (August 2019).
...

Sheet Pre-RIA India
B1: Visa Timing ESTIMATE -- INDIA Unreserved
B3: Background
B4: Estimated total Pre-RIA EB-5 Unreserved pipeline backlog
C5: China | D5: India | E5: ROW | F5: Total
B6: as of June 2025
D8: 0.82 | E8: Average pre-RIA I-526 approval rate in 2024
D9: 2.5359256 | E9: Average visas per investor applicant in 2021-2023 (worldwide, AOS+consular)
D10: 0.55 | E10: Average % of visas issued through consulates (2018-2023)
C12: India | D12: India
B13: Visa Bulletin | C13: Chart A | D13: Chart B
B14: 44835 | C14: 43777 | D14: 43807
B15: 45200 | C15: 43449 | D15: 44652
B16: 45566 | C16: 44562 | D16: 44652
B17: 45931 | C17: 44228 | D17: 44652
B19: Unreserved India VISA DEMAND ESTIMATE as of June 2024 | G19: =D8*D9*D10 -> 1.1437025 | M19: VISA SUPPLY ESTIMATE from June 2024
